Workbook

Sheet Backtest Candle 18
A1: Data | B1: Dia | C1: Setup | D1: Direção | E1: Foi contra antes de pagar | F1: Quanto pagou a favor | G1: WIN / LOSS | H1: POSSIVEL REENTRADA em dia de loss | I1: Coluna 2 | J1: Coluna 3
A2: 46023 | B2: QUI | C2: ROMP. CANDLE 18 | G2: WIN
A3: 46024 | B3: SEX | C3: ROMP. CANDLE 18 | D3: VENDA | F3: 200+ | G3: WIN
A4: 46027 | B4: SEG | C4: ROMP. CANDLE 18 | D4: VENDA | E4: 200 | G4: LOSS | H4: se entrar de novo, paga. | L4: total | M4: 45 | N4: =M4/M4 -> 1
A5: 46028 | B5: TER | C5: ROMP. CANDLE 18 | D5: VENDA | F5: 200+ | G5: WIN
A6: 46029 | B6: QUA | C6: ROMP. CANDLE 18 | D6: VENDA | F6: 200+ | G6: WIN
A7: 46030 | B7: QUI | C7: ROMP. CANDLE 18 | D7: COMPRA | E7: 150 | F7: 125 | G7: WIN | H7: se entrar de novo, paga.
A8: 46031 | B8: SEX | C8: ROMP. CANDLE 18 | D8: COMPRA | F8: 200+ | G8: WIN
A9: 46034 | B9: SEG | C9: ROMP. CANDLE 18 | D9: COMPRA | F9: 150 | G9: WIN
A10: 46035 | B10: TER | C10: ROMP. CANDLE 18 | D10: VENDA | E10: 150 | F10: 200+ | G10: WIN | H10: se entrar de novo, paga.
A11: 46036 | B11: QUA | C11: ROMP. CANDLE 18 | D11: COMPRA | F11: 175 | G11: WIN
A12: 46037 | B12: QUI | C12: ROMP. CANDLE 18 | D12: VENDA | F12: 150 | G12: WIN
A13: 46038 | B13: SEX | C13: ROMP. CANDLE 18 | D13: VENDA | F13: 100 | G13: WIN
A14: 46041 | B14: SEG | C14: ROMP. CANDLE 18 | D14: COMPRA | F14: 150 | G14: WIN
A15: 46042 | B15: TER | C15: ROMP. CANDLE 18 | D15: COMPRA | F15: 200+ | G15: WIN
A16: 46043 | B16: QUA | C16: ROMP. CANDLE 18 | D16: COMPRA | F16: 200+ | G16: WIN
A17: 46044 | B17: QUI | C17: ROMP. CANDLE 18 | H17: nao rompeu no candle seguinte | I17: pos - win
A18: 46045 | B18: SEX | C18: ROMP. CANDLE 18 | H18: nao rompeu no candle seguinte | I18: pos - win
A19: 46048 | B19: SEG | C19: ROMP. CANDLE 18 | D19: COMPRA | F19: 200+ | G19: WIN
A20: 46049 | B20: TER | C20: ROMP. CANDLE 18 | D20: VENDA | F20: 100 | G20: WIN
A21: 46050 | B21: QUA | C21: ROMP. CANDLE 18 | D21: VENDA | E21: 200 | G21: LOSS | H21: se entrar de novo, paga. | L21: pagam | M21: 21 | N21: =M21/M4 -> 0.46666667
A22: 46051 | B22: QUI | C22: ROMP. CANDLE 18 | D22: VENDA | F22: 200+ | G22: WIN
A23: 46052 | B23: SEX | C23: ROMP. CANDLE 18 | D23: COMPRA | E23: 175 | F23: 150 | G23: LOSS | H23: se entrar de novo, paga. | L23: nao entrou | M23: 12 | N23: =M23/M4 -> 0.26666667
A24: 46055 | B24: SEG | C24: ROMP. CANDLE 18 | D24: VENDA | F24: 100 | G24: WIN
A25: 46056 | B25: TER | C25: ROMP. CANDLE 18 | D25: COMPRA | F25: 200+ | G25: WIN
A26: 46057 | B26: QUA | C26: ROMP. CANDLE 18 | D26: COMPRA | E26: 200 | G26: LOSS | H26: nao rompeu pro mesmo lado | L26: stops | M26: 12 | N26: =M26/M4 -> 0.26666667
A27: 46058 | B27: QUI | C27: ROMP. CANDLE 18 | D27: VENDA | E27: 200 | G27: LOSS | H27: se entrar de novo, paga.
A28: 46059 | B28: SEX | C28: ROMP. CANDLE 18 | D28: VENDA | E28: 200 | G28: LOSS | H28: se entrar de novo, paga.
A29: 46062 | B29: SEG | C29: ROMP. CANDLE 18 | D29: VENDA | E29: 200 | G29: LOSS | H29: se entrar de novo, stopado.
A30: 46063 | B30: IPCA - TER | C30: ROMP. CANDLE 18 | D30: COMPRA | E30: 200 | G30: LOSS | H30: se entrar de novo, stopado.
A31: 46064 | B31: QUA | C31: ROMP. CANDLE 18 | D31: VENDA | E31: 200 | G31: LOSS | H31: se entrar de novo, paga.
A32: 46065 | B32: QUI | C32: ROMP. CANDLE 18 | D32: VENDA | E32: 150 | F32: 200+ | G32: WIN | H32: se entrar de novo, paga.
A33: 46066 | B33: SEX | C33: ROMP. CANDLE 18 | D33: COMPRA | E33: 200 | G33: LOSS | H33: nao rompeu pro mesmo lado
A34: 46069 | B34: SEG | C34: ROMP. CANDLE 18 | H34: feriado
A35: 46070 | B35: TER | C35: ROMP. CANDLE 18 | H35: feriado
A36: 46071 | B36: QUA | C36: ROMP. CANDLE 18 | H36: quarta feira de cinzas
A37: 46072 | B37: QUI | C37: ROMP. CANDLE 18 | H37: nao rompeu no candle seguinte | I37: pos - win
A38: 46073 | B38: SEX | C38: ROMP. CANDLE 18 | D38: COMPRA | F38: 125 | G38: WIN
A39: 46076 | B39: SEG | C39: ROMP. CANDLE 18 | D39: COMPRA | F39: 200+ | G39: WIN
A40: 46077 | B40: TER | C40: ROMP. CANDLE 18 | D40: VENDA | F40: 200+ | G40: WIN
...

Sheet QUANTO PAGARAM
A1: TESTE | E1: Desfecho | F1: VALORES FEITOS | G1: PONTOS QUE TIROU
A2: 1 PARCIAL - 100 | B2: 0.2 | C2: 46024 | D2: SEX | E2: 2ª PARCIAL | F2: 720
A3: 2 PARCIAL - 200 | B3: 0.2 | C3: 46028 | D3: TER | E3: 2ª PARCIAL | F3: 720
A4: 3 PARCIAL - 400 | B4: 0.3 | C4: 46029 | D4: QUA | E4: 3ª PARCIAL | F4: 2970 | G4: 240
A5: 4 PARCIAL DEIXA CORRER | B5: 0.3 | C5: 46031 | D5: SEX | E5: 3ª PARCIAL | F5: 3312 | G5: 320
A6: ZERO A ZERO POS PRIMEIRA PARCIAL | C6: 46035 | D6: TER | E6: 3ª PARCIAL | F6: 4446 | G6: 635
A7: CONDUCAO DE CANDLE ATE ROMPER O ULTIMO | C7: 46042 | D7: TER | E7: 4ª PARCIAL | F7: 5706 | G7: 870 | H7: FIZ UMA PARCIAL COM 1000 E SEGUREI 9 E TIROU COM ISSO
C8: 46043 | D8: QUA | E8: 3ª PARCIAL | F8: 4338 | G8: 620
C9: 46048 | D9: SEG | E9: 4ª PARCIAL | F9: 7554 | G9: 1800 | H9: um candle correu 2k de pontos absurdo
C10: 46051 | D10: QUI | E10: 2ª PARCIAL | F10: 720
C11: 46056 | D11: TER | E11: 2ª PARCIAL | F11: 720
C12: 46065 | D12: QUI | E12: 2ª PARCIAL | F12: 720
C13: 46076 | D13: SEG | E13: 3ª PARCIAL | F13: 5850 | G13: 1050
C14: 46077 | D14: TER | E14: 2ª PARCIAL | F14: 720
C15: 46079 | D15: QUI | E15: 2ª PARCIAL | F15: 720
C16: 46084 | D16: TER | E16: 2ª PARCIAL | F16: 720
C17: 46099 | D17: QUA | E17: 3ª PARCIAL | F17: 2160
C18: 46101 | D18: SEX | E18: 2ª PARCIAL | F18: 720
C19: 46106 | D19: QUA | E19: 2ª PARCIAL | F19: 720
C20: 46115 | D20: SEX
C21: 46120 | D21: QUA | E21: 4ª PARCIAL | F21: 5634 | G21: 760 | H21: pagou 1100 pontos
C22: 46122 | D22: SEX | E22: 2ª PARCIAL | F22: 720
C23: 46128 | D23: QUI | E23: 3ª PARCIAL | F23: 3024 | G23: 250
C24: 46129 | D24: SEX | E24: 2ª PARCIAL | F24: 720
C25: 46134 | D25: QUA | E25: 4ª PARCIAL | F25: 4932 | G25: 495
C26: 46136 | D26: SEX | E26: 2ª PARCIAL | F26: 720
C27: 46139 | D27: SEG | E27: 2ª PARCIAL | F27: 720
C28: 46147 | D28: TER | E28: 3ª PARCIAL | F28: 3168
C29: 46148 | D29: QUA | E29: 2ª PARCIAL | F29: 720
C30: 46149 | D30: QUI | E30: 4ª PARCIAL | F30: 6552 | G30: 1440 | H30: pagou 1800 pontos
C31: 46154 | D31: TER | E31: 3ª PARCIAL | F31: 3654 | G31: 415
C32: 46155 | D32: QUA | E32: 3ª PARCIAL | F32: 3366 | G32: 350
C33: 46157 | D33: SEX | E33: 2ª PARCIAL | F33: 720
C34: 46161 | D34: TER | E34: 4ª PARCIAL | F34: 6633 | G34: 1450 | H34: pagou 1700 pontos
C35: 46164 | D35: SEX | E35: 2ª PARCIAL | F35: 720
C36: 46169 | D36: QUA | E36: 4ª PARCIAL | F36: 5085 | G36: 625 | H36: pagou 1100 pontos
C37: 46174 | D37: SEG | E37: 2ª PARCIAL | F37: 720
C38: 46181 | D38: SEG | E38: 3ª PARCIAL | F38: 2160 | G38: 100
C39: 46182 | D39: TER | E39: 2ª PARCIAL | F39: 720
C40: 46190 | D40: QUA | E40: 3ª PARCIAL | F40: 2160
...

Sheet REENTRADA
I1: pontos antes do zero a zero | J1: voltou no zero a zero? | K1: stopou? (stop 170 pontos) | L1: total de pontos que correu | M1: conducao de candle
A2: 46027 | B2: SEG | C2: ROMP. CANDLE 18 | D2: VENDA | E2: 200 | G2: LOSS | H2: se entrar de novo, paga. | I2: 175 | J2: sim | K2: nao | L2: 585 | M2: 390
A3: 46050 | B3: QUA | C3: ROMP. CANDLE 18 | D3: VENDA | E3: 200 | G3: LOSS | H3: se entrar de novo, paga. | I3: 240 | J3: sim | K3: sim | L3: 240
A4: 46052 | B4: SEX | C4: ROMP. CANDLE 18 | D4: COMPRA | E4: 175 | F4: 150 | G4: LOSS | H4: se entrar de novo, paga. | I4: 100 | J4: sim | K4: sim | L4: 150
A5: 46058 | B5: QUI | C5: ROMP. CANDLE 18 | D5: VENDA | E5: 200 | G5: LOSS | H5: se entrar de novo, paga. | I5: 175 | J5: sim | K5: sim | L5: 335
A6: 46059 | B6: SEX | C6: ROMP. CANDLE 18 | D6: VENDA | E6: 200 | G6: LOSS | H6: se entrar de novo, paga. | I6: 315 | J6: sim | K6: nao | L6: 350 | M6: 0
A7: 46064 | B7: QUA | C7: ROMP. CANDLE 18 | D7: VENDA | E7: 200 | G7: LOSS | H7: se entrar de novo, paga. | I7: 125 | J7: sim | K7: sim | L7: 125
A8: 46085 | B8: QUA | C8: ROMP. CANDLE 18 | D8: VENDA | E8: 200 | G8: LOSS | H8: se entrar de novo, paga. | I8: 1275 | J8: nao | K8: nao | L8: 1275 | M8: 720
A9: 46093 | B9: IPCA - QUI | C9: ROMP. CANDLE 18 | D9: VENDA | E9: 200 | G9: LOSS | H9: se entrar de novo, paga. | I9: 1610 | J9: nao | K9: nao | L9: 1610 | M9: 760
A10: 46108 | B10: SEX | C10: ROMP. CANDLE 18 | D10: COMPRA | E10: 200 | G10: LOSS | H10: se entrar de novo, paga. | I10: 100 | J10: sim | K10: sim | L10: 110
A11: 46126 | B11: TER | C11: ROMP. CANDLE 18 | D11: COMPRA | E11: 200 | G11: LOSS | H11: se entrar de novo, paga. | I11: 125 | J11: sim | K11: nao | L11: 340 | M11: 60
A12: 46132 | B12: SEG | C12: ROMP. CANDLE 18 | D12: VENDA | E12: 200 | G12: LOSS | H12: se entrar de novo, paga. | I12: 610 | J12: nao | K12: nao | L12: 610 | M12: 315
A13: 46135 | B13: QUI | C13: ROMP. CANDLE 18 | D13: VENDA | E13: 200 | G13: LOSS | H13: se entrar de novo, paga. | I13: 125 | J13: sim | K13: nao | L13: 1040 | M13: 305
A14: 46146 | B14: SEG | C14: ROMP. CANDLE 18 | D14: COMPRA | E14: 200 | G14: LOSS | H14: se entrar de novo, paga. | I14: 100 | J14: sim | K14: nao | L14: 610 | M14: 320
A15: 46162 | B15: QUA | C15: ROMP. CANDLE 18 | D15: COMPRA | E15: 200 | G15: LOSS | H15: se entrar de novo, paga. | I15: 490 | J15: nao | K15: nao | L15: 490 | M15: 95
A16: 46189 | B16: TER | C16: ROMP. CANDLE 18 | D16: COMPRA | E16: 200 | G16: LOSS | H16: se entrar de novo, paga. | I16: 350 | J16: sim | K16: sim | L16: 350
A17: 46211 | B17: QUA | C17: ROMP. CANDLE 18 | D17: COMPRA | E17: 175 | F17: 175 | G17: LOSS | H17: se entrar de novo, paga. | I17: 125 | J17: sim | K17: sim | L17: 150
A18: 46231 | B18: TER | C18: ROMP. CANDLE 18 | D18: VENDA | E18: 200 | G18: LOSS | H18: se entrar de novo, paga. | I18: 180 | J18: sim | K18: sim | L18: 180
A19: 46233 | B19: QUI | C19: ROMP. CANDLE 18 | D19: VENDA | E19: 200 | G19: LOSS | H19: se entrar de novo, paga. | I19: 330 | J19: sim | K19: sim | L19: 330
A20: 46267 | B20: QUA | C20: ROMP. CANDLE 18 | D20: COMPRA | E20: 200 | G20: LOSS | H20: se entrar de novo, paga. | I20: 305 | J20: sim | K20: nao | L20: 3200 | M20: 2740
A21: 46276 | B21: IPCA - SEX | C21: ROMP. CANDLE 18 | D21: VENDA | E21: 200 | G21: LOSS | H21: se entrar de novo, paga. | I21: 375 | J21: sim | K21: nao | L21: 645 | M21: 0
A22: 46286 | B22: SEG | C22: ROMP. CANDLE 18 | D22: VENDA | E22: 175 | G22: LOSS | H22: se entrar de novo, paga.
A24: 46030 | B24: QUI | C24: ROMP. CANDLE 18 | D24: COMPRA | E24: 150 | F24: 125 | G24: WIN | H24: se entrar de novo, paga. | I24: 100 | J24: sim | K24: nao | L24: 450 | M24: 175
A25: 46035 | B25: TER | C25: ROMP. CANDLE 18 | D25: VENDA | E25: 150 | F25: 200+ | G25: WIN | H25: se entrar de novo, paga. | I25: 275 | J25: nao | K25: nao | L25: 275 | M25: 115
A26: 46065 | B26: QUI | C26: ROMP. CANDLE 18 | D26: VENDA | E26: 150 | F26: 200+ | G26: WIN | H26: se entrar de novo, paga. | I26: 240 | J26: sim | K26: nao | L26: 410 | M26: 35
A27: 46155 | B27: QUA | C27: ROMP. CANDLE 18 | D27: VENDA | E27: 100 | F27: 200+ | G27: WIN | H27: se entrar de novo, paga. | I27: 810 | J27: nao | K27: nao | L27: 810 | M27: 380
A28: 46163 | B28: QUI | C28: ROMP. CANDLE 18 | D28: VENDA | E28: 150 | F28: 175 | G28: WIN | H28: se entrar de novo, paga. | I28: 140 | J28: sim | K28: sim | L28: 305
A29: 46167 | B29: SEG | C29: ROMP. CANDLE 18 | D29: COMPRA | E29: 150 | F29: 150 | G29: WIN | H29: se entrar de novo, paga. | I29: 145 | J29: sim | K29: nao | L29: 280 | M29: 0
A30: 46182 | B30: TER | C30: ROMP. CANDLE 18 | D30: COMPRA | E30: 125 | F30: 200+ | G30: WIN | H30: se entrar de novo, paga. | I30: 395 | J30: sim | K30: sim | L30: 395
A31: 46247 | B31: QUI | C31: ROMP. CANDLE 18 | D31: COMPRA | E31: 150 | F31: 200+ | G31: WIN | H31: se entrar de novo, paga. | I31: 635 | J31: nao | K31: nao | L31: 635 | M31: 375
A32: 46261 | B32: QUI | C32: ROMP. CANDLE 18 | D32: VENDA | E32: 100 | F32: 150 | G32: WIN | H32: se entrar de novo, paga. | I32: 150 | J32: sim | K32: sim | L32: 150
A33: 46262 | B33: SEX | C33: ROMP. CANDLE 18 | D33: VENDA | E33: 100 | F33: 125 | G33: WIN | H33: se entrar de novo, paga. | I33: 130 | J33: sim | K33: sim | L33: 130
A34: 46265 | B34: SEG | C34: ROMP. CANDLE 18 | D34: COMPRA | E34: 125 | F34: 150 | G34: WIN | H34: se entrar de novo, paga. | I34: 160 | J34: sim | K34: sim | L34: 160
A35: 46266 | B35: TER | C35: ROMP. CANDLE 18 | D35: COMPRA | E35: 125 | F35: 200+ | G35: WIN | H35: se entrar de novo, paga. | I35: 1360 | J35: nao | K35: nao | L35: 1360 | M35: 780
A36: 46268 | B36: QUI | C36: ROMP. CANDLE 18 | D36: VENDA | E36: 125 | F36: 200+ | G36: WIN | H36: se entrar de novo, paga. | I36: 570 | J36: sim | K36: sim | L36: 570
A37: 46279 | B37: SEG | C37: ROMP. CANDLE 18 | D37: VENDA | E37: 125 | F37: 175 | G37: WIN | H37: se entrar de novo, paga. | I37: 190 | J37: sim | K37: sim | L37: 190

Sheet TOTAL MES
B1: MAIS DE 200 PONTOS | C1: 0X0 | D1: LOSSES | E1: TOTAL
A2: JANEIRO | B2: =SUM('QUANTO PAGARAM'!F2:F10) -> 30486 | C2: =6*240 -> 1440 | D2: =3*(-2040) -> -6120 | E2: =SUM(B2:D2) -> 25806
A3: FEVEREIRO | B3: =SUM('QUANTO PAGARAM'!F11:F15) -> 8730 | C3: =4*240 -> 960 | D3: =7*(-2040) -> -14280 | E3: =SUM(B3:D3) -> -4590
A4: MARCO | B4: =SUM('QUANTO PAGARAM'!F16:F19) -> 4320 | C4: =8*240 -> 1920 | D4: =10*(-2040) -> -20400 | E4: =SUM(B4:D4) -> -14160
A5: ABRIL | B5: =SUM('QUANTO PAGARAM'!F20:F27) -> 16470 | C5: =4*240 -> 960 | D5: =4*(-2040) -> -8160 | E5: =SUM(B5:D5) -> 9270
A6: MAIO | B6: =SUM('QUANTO PAGARAM'!F28:F36) -> 30618 | C6: =6*240 -> 1440 | D6: =4*(-2040) -> -8160 | E6: =SUM(B6:D6) -> 23898
A7: JUNHO | B7: =SUM('QUANTO PAGARAM'!F37:F44) -> 16866 | C7: =7*240 -> 1680 | D7: =5*(-2040) -> -10200 | E7: =SUM(B7:D7) -> 8346
A8: JULHO | B8: =SUM('QUANTO PAGARAM'!F45:F52) -> 18504 | C8: =5*240 -> 1200 | D8: =7*(-2040) -> -14280 | E8: =SUM(B8:D8) -> 5424
A9: AGOSTO | B9: =SUM('QUANTO PAGARAM'!F53:F61) -> 32724 | C9: =10*240 -> 2400 | D9: =1*(-2040) -> -2040 | E9: =SUM(B9:D9) -> 33084
A10: SETEMBRO | B10: =SUM('QUANTO PAGARAM'!F62:F63) -> 7461 | C10: =3*240 -> 720 | D10: =3*(-2040) -> -6120 | E10: =SUM(B10:D10) -> 2061

Sheet Dashboard
A1: BACKTEST — STOP x PRIMEIRA PARCIAL | CANDLE 18
A3: Stop analisado | B3: Parcial analisada | C3: Trades que pagaram | D3: Seriam stopados antes | E3: Sobreviveriam | F3: % sobrevivência | H3: COMO LER
A4: 100 | B4: 100 | C4: =COUNTIF('Backtest Candle 18'!F2:F180,"100")+COUNTIF('Backtest Candle 18'!F2:F180,"125")+COUNTIF('Backtest Candle 18'!F2:F180,"150")+COUNTIF('Backtest Candle 18'!F2:F180,"175")+COUNTIF('Backtest Candle 18'!F2:F180,"200")+COUNTIF('Backtest Candle 18'!F2:F180,"200+") -> 122 | D4: =COUNTIF('Backtest Candle 18'!E2:E180,"100")+COUNTIF('Backtest Candle 18'!E2:E180,"125")+COUNTIF('Backtest Candle 18'!E2:E180,"150")+COUNTIF('Backtest Candle 18'!E2:E180,"175")+COUNTIF('Backtest Candle 18'!E2:E180,"200")+COUNTIF('Backtest Candle 18'!E2:E180,">200") -> 54 | E4: =MAX(0,C4-D4) -> 68 | F4: =IF(C4=0,"",E4/C4) -> 0.55737705 | H4: 1 | I4: Na base, você só escolhe faixas fixas.
A5: 100 | B5: 125 | C5: =COUNTIF('Backtest Candle 18'!F2:F180,"125")+COUNTIF('Backtest Candle 18'!F2:F180,"150")+COUNTIF('Backtest Candle 18'!F2:F180,"175")+COUNTIF('Backtest Candle 18'!F2:F180,"200")+COUNTIF('Backtest Candle 18'!F2:F180,"200+") -> 106 | D5: =COUNTIF('Backtest Candle 18'!E2:E180,"100")+COUNTIF('Backtest Candle 18'!E2:E180,"125")+COUNTIF('Backtest Candle 18'!E2:E180,"150")+COUNTIF('Backtest Candle 18'!E2:E180,"175")+COUNTIF('Backtest Candle 18'!E2:E180,"200")+COUNTIF('Backtest Candle 18'!E2:E180,">200") -> 54 | E5: =MAX(0,C5-D5) -> 52 | F5: =IF(C5=0,"",E5/C5) -> 0.49056604 | H5: 2 | I5: 'Foi contra' = máxima excursão contra antes de pagar.
A6: 100 | B6: 150 | C6: =COUNTIF('Backtest Candle 18'!F2:F180,"150")+COUNTIF('Backtest Candle 18'!F2:F180,"175")+COUNTIF('Backtest Candle 18'!F2:F180,"200")+COUNTIF('Backtest Candle 18'!F2:F180,"200+") -> 89 | D6: =COUNTIF('Backtest Candle 18'!E2:E180,"100")+COUNTIF('Backtest Candle 18'!E2:E180,"125")+COUNTIF('Backtest Candle 18'!E2:E180,"150")+COUNTIF('Backtest Candle 18'!E2:E180,"175")+COUNTIF('Backtest Candle 18'!E2:E180,"200")+COUNTIF('Backtest Candle 18'!E2:E180,">200") -> 54 | E6: =MAX(0,C6-D6) -> 35 | F6: =IF(C6=0,"",E6/C6) -> 0.39325843 | H6: 3 | I6: 'Quanto pagou' = máxima excursão a favor.
A7: 100 | B7: 175 | C7: =COUNTIF('Backtest Candle 18'!F2:F180,"175")+COUNTIF('Backtest Candle 18'!F2:F180,"200")+COUNTIF('Backtest Candle 18'!F2:F180,"200+") -> 73 | D7: =COUNTIF('Backtest Candle 18'!E2:E180,"100")+COUNTIF('Backtest Candle 18'!E2:E180,"125")+COUNTIF('Backtest Candle 18'!E2:E180,"150")+COUNTIF('Backtest Candle 18'!E2:E180,"175")+COUNTIF('Backtest Candle 18'!E2:E180,"200")+COUNTIF('Backtest Candle 18'!E2:E180,">200") -> 54 | E7: =MAX(0,C7-D7) -> 19 | F7: =IF(C7=0,"",E7/C7) -> 0.26027397 | H7: 4 | I7: Depois cruzamos stop x primeira parcial.
A8: 100 | B8: 200 | C8: =COUNTIF('Backtest Candle 18'!F2:F180,"200")+COUNTIF('Backtest Candle 18'!F2:F180,"200+") -> 61 | D8: =COUNTIF('Backtest Candle 18'!E2:E180,"100")+COUNTIF('Backtest Candle 18'!E2:E180,"125")+COUNTIF('Backtest Candle 18'!E2:E180,"150")+COUNTIF('Backtest Candle 18'!E2:E180,"175")+COUNTIF('Backtest Candle 18'!E2:E180,"200")+COUNTIF('Backtest Candle 18'!E2:E180,">200") -> 54 | E8: =MAX(0,C8-D8) -> 7 | F8: =IF(C8=0,"",E8/C8) -> 0.1147541 | H8: 5 | I8: Objetivo: achar o stop mínimo que preserva os trades bons.
A9: 125 | B9: 100 | C9: =COUNTIF('Backtest Candle 18'!F2:F180,"100")+COUNTIF('Backtest Candle 18'!F2:F180,"125")+COUNTIF('Backtest Candle 18'!F2:F180,"150")+COUNTIF('Backtest Candle 18'!F2:F180,"175")+COUNTIF('Backtest Candle 18'!F2:F180,"200")+COUNTIF('Backtest Candle 18'!F2:F180,"200+") -> 122 | D9: =COUNTIF('Backtest Candle 18'!E2:E180,"125")+COUNTIF('Backtest Candle 18'!E2:E180,"150")+COUNTIF('Backtest Candle 18'!E2:E180,"175")+COUNTIF('Backtest Candle 18'!E2:E180,"200")+COUNTIF('Backtest Candle 18'!E2:E180,">200") -> 51 | E9: =MAX(0,C9-D9) -> 71 | F9: =IF(C9=0,"",E9/C9) -> 0.58196721
A10: 125 | B10: 125 | C10: =COUNTIF('Backtest Candle 18'!F2:F180,"125")+COUNTIF('Backtest Candle 18'!F2:F180,"150")+COUNTIF('Backtest Candle 18'!F2:F180,"175")+COUNTIF('Backtest Candle 18'!F2:F180,"200")+COUNTIF('Backtest Candle 18'!F2:F180,"200+") -> 106 | D10: =COUNTIF('Backtest Candle 18'!E2:E180,"125")+COUNTIF('Backtest Candle 18'!E2:E180,"150")+COUNTIF('Backtest Candle 18'!E2:E180,"175")+COUNTIF('Backtest Candle 18'!E2:E180,"200")+COUNTIF('Backtest Candle 18'!E2:E180,">200") -> 51 | E10: =MAX(0,C10-D10) -> 55 | F10: =IF(C10=0,"",E10/C10) -> 0.51886792 | H10: Assertividade | I10: =COUNTIF('Backtest Candle 18'!G:G,"WIN") -> 126
A11: 125 | B11: 150 | C11: =COUNTIF('Backtest Candle 18'!F2:F180,"150")+COUNTIF('Backtest Candle 18'!F2:F180,"175")+COUNTIF('Backtest Candle 18'!F2:F180,"200")+COUNTIF('Backtest Candle 18'!F2:F180,"200+") -> 89 | D11: =COUNTIF('Backtest Candle 18'!E2:E180,"125")+COUNTIF('Backtest Candle 18'!E2:E180,"150")+COUNTIF('Backtest Candle 18'!E2:E180,"175")+COUNTIF('Backtest Candle 18'!E2:E180,"200")+COUNTIF('Backtest Candle 18'!E2:E180,">200") -> 51 | E11: =MAX(0,C11-D11) -> 38 | F11: =IF(C11=0,"",E11/C11) -> 0.42696629 | H11: Losses | I11: =COUNTIF('Backtest Candle 18'!G:G,"LOSS") -> 45 | J11: =I11*2040 -> 91800
A12: 125 | B12: 175 | C12: =COUNTIF('Backtest Candle 18'!F2:F180,"175")+COUNTIF('Backtest Candle 18'!F2:F180,"200")+COUNTIF('Backtest Candle 18'!F2:F180,"200+") -> 73 | D12: =COUNTIF('Backtest Candle 18'!E2:E180,"125")+COUNTIF('Backtest Candle 18'!E2:E180,"150")+COUNTIF('Backtest Candle 18'!E2:E180,"175")+COUNTIF('Backtest Candle 18'!E2:E180,"200")+COUNTIF('Backtest Candle 18'!E2:E180,">200") -> 51 | E12: =MAX(0,C12-D12) -> 22 | F12: =IF(C12=0,"",E12/C12) -> 0.30136986 | H12: Tx Assertividade | I12: =IF((I10+I11)=0,"",I10/(I10+I11)) -> 0.73684211
A13: 125 | B13: 200 | C13: =COUNTIF('Backtest Candle 18'!F2:F180,"200")+COUNTIF('Backtest Candle 18'!F2:F180,"200+") -> 61 | D13: =COUNTIF('Backtest Candle 18'!E2:E180,"125")+COUNTIF('Backtest Candle 18'!E2:E180,"150")+COUNTIF('Backtest Candle 18'!E2:E180,"175")+COUNTIF('Backtest Candle 18'!E2:E180,"200")+COUNTIF('Backtest Candle 18'!E2:E180,">200") -> 51 | E13: =MAX(0,C13-D13) -> 10 | F13: =IF(C13=0,"",E13/C13) -> 0.16393443
A14: 150 | B14: 100 | C14: =COUNTIF('Backtest Candle 18'!F2:F180,"100")+COUNTIF('Backtest Candle 18'!F2:F180,"125")+COUNTIF('Backtest Candle 18'!F2:F180,"150")+COUNTIF('Backtest Candle 18'!F2:F180,"175")+COUNTIF('Backtest Candle 18'!F2:F180,"200")+COUNTIF('Backtest Candle 18'!F2:F180,"200+") -> 122 | D14: =COUNTIF('Backtest Candle 18'!E2:E180,"150")+COUNTIF('Backtest Candle 18'!E2:E180,"175")+COUNTIF('Backtest Candle 18'!E2:E180,"200")+COUNTIF('Backtest Candle 18'!E2:E180,">200") -> 47 | E14: =MAX(0,C14-D14) -> 75 | F14: =IF(C14=0,"",E14/C14) -> 0.6147541
A15: 150 | B15: 125 | C15: =COUNTIF('Backtest Candle 18'!F2:F180,"125")+COUNTIF('Backtest Candle 18'!F2:F180,"150")+COUNTIF('Backtest Candle 18'!F2:F180,"175")+COUNTIF('Backtest Candle 18'!F2:F180,"200")+COUNTIF('Backtest Candle 18'!F2:F180,"200+") -> 106 | D15: =COUNTIF('Backtest Candle 18'!E2:E180,"150")+COUNTIF('Backtest Candle 18'!E2:E180,"175")+COUNTIF('Backtest Candle 18'!E2:E180,"200")+COUNTIF('Backtest Candle 18'!E2:E180,">200") -> 47 | E15: =MAX(0,C15-D15) -> 59 | F15: =IF(C15=0,"",E15/C15) -> 0.55660377 | I15: =164-58 -> 106
A16: 150 | B16: 150 | C16: =COUNTIF('Backtest Candle 18'!F2:F180,"150")+COUNTIF('Backtest Candle 18'!F2:F180,"175")+COUNTIF('Backtest Candle 18'!F2:F180,"200")+COUNTIF('Backtest Candle 18'!F2:F180,"200+") -> 89 | D16: =COUNTIF('Backtest Candle 18'!E2:E180,"150")+COUNTIF('Backtest Candle 18'!E2:E180,"175")+COUNTIF('Backtest Candle 18'!E2:E180,"200")+COUNTIF('Backtest Candle 18'!E2:E180,">200") -> 47 | E16: =MAX(0,C16-D16) -> 42 | F16: =IF(C16=0,"",E16/C16) -> 0.47191011 | I16: 58 | J16: =I16*1200 -> 69600
A17: 150 | B17: 175 | C17: =COUNTIF('Backtest Candle 18'!F2:F180,"175")+COUNTIF('Backtest Candle 18'!F2:F180,"200")+COUNTIF('Backtest Candle 18'!F2:F180,"200+") -> 73 | D17: =COUNTIF('Backtest Candle 18'!E2:E180,"150")+COUNTIF('Backtest Candle 18'!E2:E180,"175")+COUNTIF('Backtest Candle 18'!E2:E180,"200")+COUNTIF('Backtest Candle 18'!E2:E180,">200") -> 47 | E17: =MAX(0,C17-D17) -> 26 | F17: =IF(C17=0,"",E17/C17) -> 0.35616438
A18: 150 | B18: 200 | C18: =COUNTIF('Backtest Candle 18'!F2:F180,"200")+COUNTIF('Backtest Candle 18'!F2:F180,"200+") -> 61 | D18: =COUNTIF('Backtest Candle 18'!E2:E180,"150")+COUNTIF('Backtest Candle 18'!E2:E180,"175")+COUNTIF('Backtest Candle 18'!E2:E180,"200")+COUNTIF('Backtest Candle 18'!E2:E180,">200") -> 47 | E18: =MAX(0,C18-D18) -> 14 | F18: =IF(C18=0,"",E18/C18) -> 0.2295082
A19: 175 | B19: 100 | C19: =COUNTIF('Backtest Candle 18'!F2:F180,"100")+COUNTIF('Backtest Candle 18'!F2:F180,"125")+COUNTIF('Backtest Candle 18'!F2:F180,"150")+COUNTIF('Backtest Candle 18'!F2:F180,"175")+COUNTIF('Backtest Candle 18'!F2:F180,"200")+COUNTIF('Backtest Candle 18'!F2:F180,"200+") -> 122 | D19: =COUNTIF('Backtest Candle 18'!E2:E180,"175")+COUNTIF('Backtest Candle 18'!E2:E180,"200")+COUNTIF('Backtest Candle 18'!E2:E180,">200") -> 41 | E19: =MAX(0,C19-D19) -> 81 | F19: =IF(C19=0,"",E19/C19) -> 0.66393443
A20: 175 | B20: 125 | C20: =COUNTIF('Backtest Candle 18'!F2:F180,"125")+COUNTIF('Backtest Candle 18'!F2:F180,"150")+COUNTIF('Backtest Candle 18'!F2:F180,"175")+COUNTIF('Backtest Candle 18'!F2:F180,"200")+COUNTIF('Backtest Candle 18'!F2:F180,"200+") -> 106 | D20: =COUNTIF('Backtest Candle 18'!E2:E180,"175")+COUNTIF('Backtest Candle 18'!E2:E180,"200")+COUNTIF('Backtest Candle 18'!E2:E180,">200") -> 41 | E20: =MAX(0,C20-D20) -> 65 | F20: =IF(C20=0,"",E20/C20) -> 0.61320755
A21: 175 | B21: 150 | C21: =COUNTIF('Backtest Candle 18'!F2:F180,"150")+COUNTIF('Backtest Candle 18'!F2:F180,"175")+COUNTIF('Backtest Candle 18'!F2:F180,"200")+COUNTIF('Backtest Candle 18'!F2:F180,"200+") -> 89 | D21: =COUNTIF('Backtest Candle 18'!E2:E180,"175")+COUNTIF('Backtest Candle 18'!E2:E180,"200")+COUNTIF('Backtest Candle 18'!E2:E180,">200") -> 41 | E21: =MAX(0,C21-D21) -> 48 | F21: =IF(C21=0,"",E21/C21) -> 0.53932584
A22: 175 | B22: 175 | C22: =COUNTIF('Backtest Candle 18'!F2:F180,"175")+COUNTIF('Backtest Candle 18'!F2:F180,"200")+COUNTIF('Backtest Candle 18'!F2:F180,"200+") -> 73 | D22: =COUNTIF('Backtest Candle 18'!E2:E180,"175")+COUNTIF('Backtest Candle 18'!E2:E180,"200")+COUNTIF('Backtest Candle 18'!E2:E180,">200") -> 41 | E22: =MAX(0,C22-D22) -> 32 | F22: =IF(C22=0,"",E22/C22) -> 0.43835616
A23: 175 | B23: 200 | C23: =COUNTIF('Backtest Candle 18'!F2:F180,"200")+COUNTIF('Backtest Candle 18'!F2:F180,"200+") -> 61 | D23: =COUNTIF('Backtest Candle 18'!E2:E180,"175")+COUNTIF('Backtest Candle 18'!E2:E180,"200")+COUNTIF('Backtest Candle 18'!E2:E180,">200") -> 41 | E23: =MAX(0,C23-D23) -> 20 | F23: =IF(C23=0,"",E23/C23) -> 0.32786885
A24: 200 | B24: 100 | C24: =COUNTIF('Backtest Candle 18'!F2:F180,"100")+COUNTIF('Backtest Candle 18'!F2:F180,"125")+COUNTIF('Backtest Candle 18'!F2:F180,"150")+COUNTIF('Backtest Candle 18'!F2:F180,"175")+COUNTIF('Backtest Candle 18'!F2:F180,"200")+COUNTIF('Backtest Candle 18'!F2:F180,"200+") -> 122 | D24: =COUNTIF('Backtest Candle 18'!E2:E180,"200")+COUNTIF('Backtest Candle 18'!E2:E180,">200") -> 39 | E24: =MAX(0,C24-D24) -> 83 | F24: =IF(C24=0,"",E24/C24) -> 0.68032787
A25: 200 | B25: 125 | C25: =COUNTIF('Backtest Candle 18'!F2:F180,"125")+COUNTIF('Backtest Candle 18'!F2:F180,"150")+COUNTIF('Backtest Candle 18'!F2:F180,"175")+COUNTIF('Backtest Candle 18'!F2:F180,"200")+COUNTIF('Backtest Candle 18'!F2:F180,"200+") -> 106 | D25: =COUNTIF('Backtest Candle 18'!E2:E180,"200")+COUNTIF('Backtest Candle 18'!E2:E180,">200") -> 39 | E25: =MAX(0,C25-D25) -> 67 | F25: =IF(C25=0,"",E25/C25) -> 0.63207547
A26: 200 | B26: 150 | C26: =COUNTIF('Backtest Candle 18'!F2:F180,"150")+COUNTIF('Backtest Candle 18'!F2:F180,"175")+COUNTIF('Backtest Candle 18'!F2:F180,"200")+COUNTIF('Backtest Candle 18'!F2:F180,"200+") -> 89 | D26: =COUNTIF('Backtest Candle 18'!E2:E180,"200")+COUNTIF('Backtest Candle 18'!E2:E180,">200") -> 39 | E26: =MAX(0,C26-D26) -> 50 | F26: =IF(C26=0,"",E26/C26) -> 0.56179775
A27: 200 | B27: 175 | C27: =COUNTIF('Backtest Candle 18'!F2:F180,"175")+COUNTIF('Backtest Candle 18'!F2:F180,"200")+COUNTIF('Backtest Candle 18'!F2:F180,"200+") -> 73 | D27: =COUNTIF('Backtest Candle 18'!E2:E180,"200")+COUNTIF('Backtest Candle 18'!E2:E180,">200") -> 39 | E27: =MAX(0,C27-D27) -> 34 | F27: =IF(C27=0,"",E27/C27) -> 0.46575342
A28: 200 | B28: 200 | C28: =COUNTIF('Backtest Candle 18'!F2:F180,"200")+COUNTIF('Backtest Candle 18'!F2:F180,"200+") -> 61 | D28: =COUNTIF('Backtest Candle 18'!E2:E180,"200")+COUNTIF('Backtest Candle 18'!E2:E180,">200") -> 39 | E28: =MAX(0,C28-D28) -> 22 | F28: =IF(C28=0,"",E28/C28) -> 0.36065574
